<mujoco model="MuJoCo Model">
  <compiler angle="radian" meshdir="./meshes/"/>

  <default>
    <default class="stretch">
      <geom mass="0" solref="0.005 1"/>
      <general biastype="affine"/>
      <default class="wheel">
        <joint axis="0 0 -1" damping=".3"/>
        <motor ctrlrange="-1 1" gear="3" forcerange="-100 100"/>
      </default>
      <default class="lift">
        <joint type="slide" axis="0 0 1" damping="5" range="-0.5 .6"/>
        <general ctrlrange="-0.5 .6" gainprm="300" biasprm="0 -300 -50" forcerange="-56 56"/>
      </default>
      <default class="telescope">
        <joint type="slide" axis="0 0 1" damping="5" range="0 0.13"/>
        <general ctrlrange="0 0.52" gainprm="100" biasprm="0 -100 -10" forcerange="-56 56"/>
      </default>
      <default class="head">
        <joint axis="0 0 1" damping="1"/>
        <position kp="10"/>
        <default class="head_pan">
          <joint range="-3.9 1.5"/>
          <position ctrlrange="-3.9 1.5"/>
        </default>
        <default class="head_tilt">
          <joint range="-1.53 0.79"/>
          <position ctrlrange="-1.53 0.79"/>
        </default>
      </default>
      <default class="wrist">
        <joint axis="0 0 -1" range="-1.75 4" damping=".1"/>
        <general gainprm="1" biasprm="0 -1 0" ctrlrange="-1.75 4" forcerange="-5 5"/>
      </default>
      <default class="finger_open">
        <joint axis="0 0 1" range="-0.6 0.6" damping=".1"/>
      </default>
      <default class="finger_slide">
        <joint type="slide" axis="1 0 0" range="-0.005 .04" damping=".1"/>
        <general gainprm="2000" biasprm="0 -2000 -200" ctrlrange="-0.005 .04"/>
      </default>
      <default class="visual">
        <geom group="2" type="mesh" contype="0" conaffinity="0"/>
      </default>
      <default class="collision">
        <geom group="3" type="mesh"/>
        <default class="caster">
          <geom type="sphere" size=".02" pos="-0.24 0 .02" condim="1" priority="1"/>
        </default>
        <default class="rubber">
          <geom condim="6" friction="0.8 0.02 0.01" priority="1"/>
        </default>
      </default>
    </default>
  </default>
  <asset>

    <material name="Caster_Rollers_Red" rgba="0.8 0.001381 0 1"/>
    <material name="Generic_Black" rgba="0.036889 0.036889 0.036889 1"/>
    <material name="3D_Print_Black" rgba="0.114435 0.114435 0.114435 1"/>
    <material name="Pantone_Black_6_U" rgba="0.072272 0.076185 0.093059 1"/>
    <material name="Plug_White" rgba="1 1 1 1"/>
    <material name="Pure_Black" rgba="0 0 0 1"/>
    <material name="Reflective_Metal" rgba="0.8 0.8 0.8 1"/>
    <material name="Respeaker_Blue_Glow" rgba="0.006995 0.054480 0.799103 1"/>
    <material name="Runstop_White_Glow" rgba="0.8 0.8 0.8 1"/>
    <material name="Speaker_Housing_Black" rgba="0.003642 0.003642 0.003642 1"/>
    <material name="Wheel_Rubber_Gray" rgba="0.418986 0.424087 0.429225 1"/>
    <material name="Lightbar_Green" rgba="0.0 0.8 0.002964 1"/>
    <material name="Pantone_705_U" rgba="1 0.723054 0.760525 1"/>
    <material name="Pantone_Cool_Gray_4_U" rgba="0.473531 0.479320 0.485150 1"/>
    <material name="Power_Button_Green" rgba="0.010852 0.023650 0.002724 1"/>
    <material name="USB_Blue" rgba="0.000557 0.010166 0.8 1"/>
    <material name="White_Plastic" rgba="1 1 1 1"/>
    <material name="Laser_Black" rgba="0.03741 0.03741 0.03741 1"/>
    <material name="Hand_Crush_Sticker" texture="hand_crush"/>
    <material name="Stretch_Serial_Sticker" texture="serial"/>
    <material name="Aruco_Right_Base_Sticker" texture="mobile_base_right_corner_aruco_sticker"/>
    <material name="Aruco_Left_Base_Sticker" texture="mobile_base_left_corner_aruco_sticker"/>
    <material name="Hand_Pinch_Sticker" texture="hand_pinch"/>
    <material name="Carbon_Fiber" rgba="0.061246 0.061246 0.061246 1"/>
    <material name="Aruco_Inner_Wrist_Sticker" texture="arm_inner_wrist_aruco_sticker"/>
    <material name="Aruco_Top_Wrist_Sticker" texture="arm_top_wrist_aruco_sticker"/>
    <material name="suction_rubber" rgba="0.25098 0.25098 0.25098 1"/>
    <material name="Aruco_Shoulder_Sticker" texture="shoulder_aruco_sticker"/>

    <mesh name="base_link" file="base_link.STL"/>
    <mesh name="base_link_collision" file="base_link_collision.STL"/>
    <mesh name="link_ground_collision" file="link_ground_collision.STL"/>
    <mesh name="link_right_wheel" file="link_right_wheel.STL"/>
    <mesh name="link_right_wheel_collision" file="link_right_wheel_collision.STL"/>
    <mesh name="link_left_wheel" file="link_left_wheel.STL"/>
    <mesh name="link_left_wheel_collision" file="link_left_wheel_collision.STL"/>
    <mesh name="omni_wheel_m" file="omni_wheel_m.STL"/>
    <mesh name="link_mast" file="link_mast.STL"/>
    <mesh name="link_mast_collision" file="link_mast_collision.STL"/>
    <mesh name="link_lift" file="link_lift.STL"/>
    <mesh name="link_lift_collision" file="link_lift_collision.STL"/>
    <mesh name="link_arm_l4" file="link_arm_l4.STL"/>
    <mesh name="link_arm_l4_collision" file="link_arm_l4_collision.STL"/>
    <mesh name="link_arm_l3" file="link_arm_l3.STL"/>
    <mesh name="link_arm_l3_collision" file="link_arm_l3_collision.STL"/>
    <mesh name="link_arm_l2" file="link_arm_l2.STL"/>
    <mesh name="link_arm_l2_collision" file="link_arm_l2_collision.STL"/>
    <mesh name="link_arm_l1" file="link_arm_l1.STL"/>
    <mesh name="link_arm_l1_collision" file="link_arm_l1_collision.STL"/>
    <mesh name="link_arm_l0" file="link_arm_l0.STL"/>
    <mesh name="link_arm_l0_collision" file="link_arm_l0_collision.STL"/>
    <mesh name="link_wrist_yaw" file="link_wrist_yaw.STL"/>
    <mesh name="link_wrist_yaw_collision" file="link_wrist_yaw_collision.STL"/>
    <mesh name="link_head" file="link_head.STL"/>
    <mesh name="link_head_collision" file="link_head_collision.STL"/>
    <mesh name="link_head_pan" file="link_head_pan.STL"/>
    <mesh name="link_head_pan_collision" file="link_head_pan_collision.STL"/>
    <mesh name="link_head_tilt" file="link_head_tilt.STL"/>
    <mesh name="link_head_tilt_collision" file="link_head_tilt_collision.STL"/>
    <mesh name="link_aruco_right_base" file="link_aruco_right_base.STL"/>
    <mesh name="link_aruco_left_base" file="link_aruco_left_base.STL"/>
    <mesh name="link_aruco_shoulder" file="link_aruco_shoulder.STL"/>
    <mesh name="link_aruco_top_wrist" file="link_aruco_top_wrist.STL"/>
    <mesh name="link_aruco_inner_wrist" file="link_aruco_inner_wrist.STL"/>
    <mesh name="d435" file="d435.stl"/>
    <mesh name="laser" file="laser.STL"/>
    <mesh name="laser_collision" file="laser_collision.STL"/>
    <mesh name="base_imu" file="base_imu.STL"/>
    <mesh name="respeaker_base" file="respeaker_base.STL"/>
    <mesh name="link_DW3_wrist_yaw_bottom" file="link_DW3_wrist_yaw_bottom.STL"/>
    <mesh name="link_DW3_wrist_yaw_bottom_collision" file="link_DW3_wrist_yaw_bottom_collision.STL"/>
    <mesh name="link_DW3_wrist_pitch" file="link_DW3_wrist_pitch.STL"/>
    <mesh name="link_DW3_wrist_pitch_collision" file="link_DW3_wrist_pitch_collision.STL"/>
    <mesh name="link_DW3_wrist_roll" file="link_DW3_wrist_roll.STL"/>
    <mesh name="link_DW3_wrist_roll_collision" file="link_DW3_wrist_roll_collision.STL"/>
    <mesh name="link_SG3_gripper_body" file="link_SG3_gripper_body.STL"/>
    <mesh name="link_SG3_gripper_body_collision" file="link_SG3_gripper_body_collision.STL"/>
    <mesh name="link_SG3_gripper_finger_right" file="link_SG3_gripper_finger_right.STL"/>
    <mesh name="link_SG3_gripper_finger_right_collision" file="link_SG3_gripper_finger_right_collision.STL"/>
    <mesh name="link_SG3_gripper_fingertip_right" file="link_SG3_gripper_fingertip_right.STL"/>
    <mesh name="link_SG3_gripper_fingertip_right_collision" file="link_SG3_gripper_fingertip_right_collision.STL"/>
    <mesh name="link_SG3_aruco_fingertip_right" file="link_SG3_aruco_fingertip_right.STL"/>
    <mesh name="link_SG3_gripper_finger_left" file="link_SG3_gripper_finger_left.STL"/>
    <mesh name="link_SG3_gripper_finger_left_collision" file="link_SG3_gripper_finger_left_collision.STL"/>
    <mesh name="link_SG3_gripper_fingertip_left" file="link_SG3_gripper_fingertip_left.STL"/>
    <mesh name="link_SG3_gripper_fingertip_left_collision" file="link_SG3_gripper_fingertip_left_collision.STL"/>
    <mesh name="link_SG3_aruco_fingertip_left" file="link_SG3_aruco_fingertip_left.STL"/>
    <mesh name="link_SG3_aruco_d405" file="link_SG3_aruco_d405.STL"/>
    <mesh name="link_SE3_head_nav_cam" file="link_SE3_head_nav_cam.STL"/>
    <mesh name="link_SE3_head_nav_cam_collision" file="link_SE3_head_nav_cam_collision.STL"/>
    <material name="grid" texture="grid" texrepeat="1 1" texuniform="true" reflectance=".2"/>
    <texture name="grid" type="2d" builtin="checker" width="512" height="512" rgb1=".1 .2 .3" rgb2=".2 .3 .4"/>

  </asset>
  <worldbody>
    <geom type="mesh" contype="0" conaffinity="0" group="1" density="0" rgba="0.79216 0.81961 0.93333 1" mesh="base_link"/>
    <geom type="mesh" rgba="0.79216 0.81961 0.93333 1" mesh="base_link_collision"/>
    <geom pos="-0.1 -0.3185 0" quat="0.707105 0 0 -0.707108" type="mesh" contype="0" conaffinity="0" group="1" density="0" rgba="0.792157 0.819608 0.933333 1" mesh="link_ground_collision"/>
    <geom pos="-0.1 -0.3185 0" quat="0.707105 0 0 -0.707108" type="mesh" rgba="0.792157 0.819608 0.933333 1" mesh="link_ground_collision"/>
    <geom size="0.032" pos="-0.245 0 0.032" quat="0.707107 -0.707107 0 0"/>
    <geom pos="-0.245 0 0.032" quat="0.707107 -0.707107 0 0" type="mesh" contype="0" conaffinity="0" group="1" density="0" rgba="0.792157 0.819608 0.933333 1" mesh="omni_wheel_m"/>
    <geom pos="-0.067 0.135 0.0284" quat="0.707105 0.707108 0 0" type="mesh" contype="0" conaffinity="0" group="1" density="0" rgba="0.79216 0.81961 0.93333 1" mesh="link_mast"/>
    <geom pos="-0.067 0.135 0.0284" quat="0.707105 0.707108 0 0" type="mesh" rgba="0.79216 0.81961 0.93333 1" mesh="link_mast_collision"/>
    <geom pos="-0.067 0.134995 1.3584" quat="-0.707107 -3.89602e-06 1.29867e-06 0.707107" type="mesh" contype="0" conaffinity="0" group="1" density="0" rgba="0.792157 0.819608 0.933333 1" mesh="link_head"/>
    <geom pos="-0.067 0.134995 1.3584" quat="-0.707107 -3.89602e-06 1.29867e-06 0.707107" type="mesh" rgba="0.792157 0.819608 0.933333 1" mesh="link_head_collision"/>
    <geom pos="-0.067 0.131964 1.40076" quat="0.939693 1.72584e-06 6.28155e-07 -0.34202" type="mesh" contype="0" conaffinity="0" group="1" density="0" rgba="0.79216 0.81961 0.93333 1" mesh="respeaker_base"/>
    <geom pos="-0.067 0.131964 1.40076" quat="0.939693 1.72584e-06 6.28155e-07 -0.34202" type="mesh" rgba="0.79216 0.81961 0.93333 1" mesh="respeaker_base"/>
    <geom pos="-0.0015028 -0.130497 0.159748" quat="0.707107 0 0 -0.707107" type="mesh" contype="0" conaffinity="0" group="1" density="0" rgba="0.792157 0.819608 0.933333 1" mesh="link_aruco_right_base"/>
    <geom pos="-0.0015028 -0.130497 0.159748" quat="0.707107 0 0 -0.707107" type="mesh" rgba="0.792157 0.819608 0.933333 1" mesh="link_aruco_right_base"/>
    <geom pos="-0.005 0.130497 0.159748" quat="0.707107 0 0 -0.707107" type="mesh" contype="0" conaffinity="0" group="1" density="0" rgba="0.792157 0.819608 0.933333 1" mesh="link_aruco_left_base"/>
    <geom pos="-0.005 0.130497 0.159748" quat="0.707107 0 0 -0.707107" type="mesh" rgba="0.792157 0.819608 0.933333 1" mesh="link_aruco_left_base"/>
    <geom pos="0.004 0 0.1664" quat="-3.67321e-06 0 0 1" type="mesh" contype="0" conaffinity="0" group="1" density="0" rgba="0.25098 0.25098 0.25098 1" mesh="laser"/>
    <geom pos="0.004 0 0.1664" quat="-3.67321e-06 0 0 1" type="mesh" rgba="0.25098 0.25098 0.25098 1" mesh="laser_collision"/>
    <geom pos="-0.12838 0.0031592 0.1474" quat="-2.59734e-06 -0.707105 0.707108 2.59735e-06" type="mesh" contype="0" conaffinity="0" group="1" density="0" rgba="0 0.772549 0.207843 1" mesh="base_imu"/>
    <geom pos="-0.12838 0.0031592 0.1474" quat="-2.59734e-06 -0.707105 0.707108 2.59735e-06" type="mesh" rgba="0 0.772549 0.207843 1" mesh="base_imu"/>
    <body name="link_right_wheel" pos="0 -0.17035 0.0508" quat="0.707105 -0.707108 0 0">
      <inertial pos="0 0 0.02765" mass="0.20773" diaginertia="5.4e-05 5.4e-05 5.1e-05"/>
      <joint name="joint_right_wheel" pos="0 0 0" axis="0 0 1" damping="21.75" frictionloss="10.48"/>
      <geom type="mesh" contype="0" conaffinity="0" group="1" density="0" rgba="0.79216 0.81961 0.93333 1" mesh="link_right_wheel"/>
      <geom type="mesh" rgba="0.79216 0.81961 0.93333 1" mesh="link_right_wheel_collision"/>
    </body>
    <body name="link_left_wheel" pos="0 0.17035 0.0508" quat="0.707105 -0.707108 0 0">
      <inertial pos="0 0 -0.02765" mass="0.20773" diaginertia="5.4e-05 5.4e-05 5.1e-05"/>
      <joint name="joint_left_wheel" pos="0 0 0" axis="0 0 1" damping="21.75" frictionloss="10.48"/>
      <geom type="mesh" contype="0" conaffinity="0" group="1" density="0" rgba="0.79216 0.81961 0.93333 1" mesh="link_left_wheel"/>
      <geom type="mesh" rgba="0.79216 0.81961 0.93333 1" mesh="link_left_wheel_collision"/>
    </body>
    <body name="link_lift" pos="-0.104385 0.134999 0.195" quat="0.707105 0 -2.59735e-06 0.707108">
      <inertial pos="-0.0319337 0.0307533 0.0199629" quat="-0.173437 0.658102 0.260234 0.684908" mass="2.22279" diaginertia="0.0124003 0.0102349 0.00537464"/>
      <joint name="joint_lift" pos="0 0 0" axis="0 0 1" type="slide" range="0 1.1" actuatorfrcrange="-100 100"/>
      <geom type="mesh" contype="0" conaffinity="0" group="1" density="0" rgba="0.79216 0.81961 0.93333 1" mesh="link_lift"/>
      <geom type="mesh" rgba="0.79216 0.81961 0.93333 1" mesh="link_lift_collision"/>
      <geom pos="-0.2547 0 0" quat="0.499998 0.5 -0.500002 -0.5" type="mesh" contype="0" conaffinity="0" group="1" density="0" rgba="0.79216 0.81961 0.93333 1" mesh="link_arm_l4"/>
      <geom pos="-0.2547 0 0" quat="0.499998 0.5 -0.500002 -0.5" type="mesh" rgba="0.79216 0.81961 0.93333 1" mesh="link_arm_l4_collision"/>
      <geom pos="-0.0133769 0.0558541 0.0861368" type="mesh" contype="0" conaffinity="0" group="1" density="0" rgba="0.792157 0.819608 0.933333 1" mesh="link_aruco_shoulder"/>
      <geom pos="-0.0133769 0.0558541 0.0861368" type="mesh" rgba="0.792157 0.819608 0.933333 1" mesh="link_aruco_shoulder"/>
      <body name="link_arm_l3" pos="-0.2677 4.77517e-08 -4.77517e-08" quat="0.499998 0.5 -0.500002 -0.5">
        <inertial pos="-1e-06 -0.000146 -0.11908" quat="0.707107 -0.000352144 0.000352144 0.707107" mass="0.146817" diaginertia="0.001081 0.001081 7.6999e-05"/>
        <joint name="joint_arm_l3" pos="0 0 0" axis="0 0 1" type="slide" range="0 0.13" actuatorfrcrange="-100 100"/>
        <geom type="mesh" contype="0" conaffinity="0" group="1" density="0" rgba="0.792157 0.819608 0.933333 1" mesh="link_arm_l3"/>
        <geom type="mesh" rgba="0.792157 0.819608 0.933333 1" mesh="link_arm_l3_collision"/>
        <body name="link_arm_l2" pos="0 0 0.013">
          <inertial pos="0 -7.1e-05 -0.115635" mass="0.130565" diaginertia="0.000943 0.000943 5.7e-05"/>
          <joint name="joint_arm_l2" pos="0 0 0" axis="0 0 1" type="slide" range="0 0.13" actuatorfrcrange="-100 100"/>
          <geom type="mesh" contype="0" conaffinity="0" group="1" density="0" rgba="0.792157 0.819608 0.933333 1" mesh="link_arm_l2"/>
          <geom type="mesh" rgba="0.792157 0.819608 0.933333 1" mesh="link_arm_l2_collision"/>
          <body name="link_arm_l1" pos="0 0 0.013">
            <inertial pos="-1e-06 -0.000121 -0.113457" mass="0.113658" diaginertia="0.0008 0.0008 4e-05"/>
            <joint name="joint_arm_l1" pos="0 0 0" axis="0 0 1" type="slide" range="0 0.13" actuatorfrcrange="-100 100"/>
            <geom type="mesh" contype="0" conaffinity="0" group="1" density="0" rgba="0.79216 0.81961 0.93333 1" mesh="link_arm_l1"/>
            <geom type="mesh" rgba="0.79216 0.81961 0.93333 1" mesh="link_arm_l1_collision"/>
            <body name="link_arm_l0" pos="0 0 -0.01375">
              <inertial pos="0.033681 -0.000847 -0.031723" quat="0.651603 -0.132908 -0.117203 0.737572" mass="0.427734" diaginertia="0.00211074 0.00186502 0.000391237"/>
              <joint name="joint_arm_l0" pos="0 0 0" axis="0 0 1" type="slide" range="0 0.13" actuatorfrcrange="-100 100"/>
              <geom type="mesh" contype="0" conaffinity="0" group="1" density="0" rgba="0.792157 0.819608 0.933333 1" mesh="link_arm_l0"/>
              <geom type="mesh" rgba="0.792157 0.819608 0.933333 1" mesh="link_arm_l0_collision"/>
              <geom pos="0.04725 0.029285 0" quat="0 0 0.707107 0.707107" type="mesh" contype="0" conaffinity="0" group="1" density="0" rgba="0.792157 0.819608 0.933333 1" mesh="link_aruco_top_wrist"/>
              <geom pos="0.04725 0.029285 0" quat="0 0 0.707107 0.707107" type="mesh" rgba="0.792157 0.819608 0.933333 1" mesh="link_aruco_top_wrist"/>
              <geom pos="0.04725 -0.0119 -0.02725" quat="0 0 1 0" type="mesh" contype="0" conaffinity="0" group="1" density="0" rgba="0.792157 0.819608 0.933333 1" mesh="link_aruco_inner_wrist"/>
              <geom pos="0.04725 -0.0119 -0.02725" quat="0 0 1 0" type="mesh" rgba="0.792157 0.819608 0.933333 1" mesh="link_aruco_inner_wrist"/>
              <body name="link_wrist_yaw" pos="0.083 -0.03075 0" quat="0 0 -0.707107 0.707107">
                <inertial pos="0.0324249 0.0120053 0.0159088" quat="-0.0785379 0.39862 0.139116 0.903095" mass="0.198971" diaginertia="0.000256572 0.000225967 8.4626e-05"/>
                <joint name="joint_wrist_yaw" pos="0 0 0" axis="0 0 -1" range="-1.75 4" actuatorfrcrange="-100 100"/>
                <geom type="mesh" contype="0" conaffinity="0" group="1" density="0" rgba="0.898039 0.917647 0.929412 1" mesh="link_wrist_yaw"/>
                <geom type="mesh" rgba="0.898039 0.917647 0.929412 1" mesh="link_wrist_yaw_collision"/>
                <geom quat="0 -0.707107 0.707107 0" type="mesh" contype="0" conaffinity="0" group="1" density="0" rgba="0.792157 0.819608 0.933333 1" mesh="link_DW3_wrist_yaw_bottom"/>
                <geom quat="0 -0.707107 0.707107 0" type="mesh" rgba="0.792157 0.819608 0.933333 1" mesh="link_DW3_wrist_yaw_bottom_collision"/>
                <body name="link_wrist_pitch" pos="0.019455 0 0.0305" quat="-0.500003 0.500001 0.499997 -0.499999">
                  <inertial pos="-0.00071148 -0.0147443 0.0195141" quat="0.515653 0.478815 -0.501674 0.503152" mass="0.116591" diaginertia="6.36768e-05 5.76475e-05 3.5776e-05"/>
                  <joint name="joint_wrist_pitch" pos="0 0 0" axis="0 0 -1" range="-1.57 0.56" actuatorfrcrange="-100 100"/>
                  <geom type="mesh" contype="0" conaffinity="0" group="1" density="0" rgba="1 1 1 1" mesh="link_DW3_wrist_pitch"/>
                  <geom type="mesh" rgba="1 1 1 1" mesh="link_DW3_wrist_pitch_collision"/>
                  <body name="link_wrist_roll" pos="-0.018859 -0.024 0.01955" quat="-2.59734e-06 0.707105 -2.59735e-06 -0.707108">
                    <inertial pos="-0.000254739 -0.00693183 0.0617709" quat="0.774132 0.632995 -0.00248324 -0.00556857" mass="0.311581" diaginertia="0.000530179 0.000390747 0.000253397"/>
                    <joint name="joint_wrist_roll" pos="0 0 0" axis="0 0 1" range="-3.14 3.14" actuatorfrcrange="-100 100"/>
                    <geom type="mesh" contype="0" conaffinity="0" group="1" density="0" rgba="0.898039 0.917647 0.929412 1" mesh="link_DW3_wrist_roll"/>
                    <geom type="mesh" rgba="0.898039 0.917647 0.929412 1" mesh="link_DW3_wrist_roll_collision"/>
                    <geom pos="0 0 0.021" quat="0 0 0 -1" type="mesh" contype="0" conaffinity="0" group="1" density="0" rgba="0.792157 0.819608 0.933333 1" mesh="link_SG3_gripper_body"/>
                    <geom pos="0 0 0.021" quat="0 0 0 -1" type="mesh" rgba="0.792157 0.819608 0.933333 1" mesh="link_SG3_gripper_body_collision"/>
                    <geom pos="0 -0.0671264 0.0507716" quat="0.0871557 0.996194 -0.000876941 7.67224e-05" type="mesh" contype="0" conaffinity="0" group="1" density="0" rgba="1 1 1 1" mesh="link_SG3_aruco_d405"/>
                    <geom pos="0 -0.0671264 0.0507716" quat="0.0871557 0.996194 -0.000876941 7.67224e-05" type="mesh" rgba="1 1 1 1" mesh="link_SG3_aruco_d405"/>
                    <body name="link_gripper_finger_right" pos="0.0246929 0 0.0581909" quat="0.52029 -0.52029 0.478851 0.478851">
                      <inertial pos="-0.112655 -0.00395171 7.26958e-05" quat="-0.00904256 0.706728 -0.00376595 0.707417" mass="0.0522659" diaginertia="8.16257e-05 8.06635e-05 3.49756e-06"/>
                      <joint name="joint_gripper_finger_right" pos="0 0 0" axis="0 0 1"/>
                      <geom type="mesh" contype="0" conaffinity="0" group="1" density="0" rgba="0.792157 0.819608 0.933333 1" mesh="link_SG3_gripper_finger_right"/>
                      <geom type="mesh" rgba="0.792157 0.819608 0.933333 1" mesh="link_SG3_gripper_finger_right_collision"/>
                      <geom pos="-0.177785 -0.0106722 0" quat="0.701057 -0.701057 -0.092296 0.092296" type="mesh" contype="0" conaffinity="0" group="1" density="0" rgba="0.25098 0.25098 0.25098 1" mesh="link_SG3_gripper_fingertip_right"/>
                      <geom pos="-0.177785 -0.0106722 0" quat="0.701057 -0.701057 -0.092296 0.092296" type="mesh" rgba="0.25098 0.25098 0.25098 1" mesh="link_SG3_gripper_fingertip_right_collision"/>
                      <geom pos="-0.143935 -0.00436382 -8.5864e-05" quat="0.564208 -0.684439 0.356297 -0.293708" type="mesh" contype="0" conaffinity="0" group="1" density="0" rgba="1 1 1 1" mesh="link_SG3_aruco_fingertip_right"/>
                      <geom pos="-0.143935 -0.00436382 -8.5864e-05" quat="0.564208 -0.684439 0.356297 -0.293708" type="mesh" rgba="1 1 1 1" mesh="link_SG3_aruco_fingertip_right"/>
                    </body>
                    <body name="link_gripper_finger_left" pos="-0.0245029 0 0.0581909" quat="-0.52029 0.52029 0.478851 0.478851">
                      <inertial pos="0.112655 -0.00395171 7.26959e-05" quat="-0.00376603 0.707417 -0.00904268 0.706728" mass="0.0522659" diaginertia="8.16258e-05 8.06635e-05 3.49756e-06"/>
                      <joint name="joint_gripper_finger_left" pos="0 0 0" axis="0 0 -1"/>
                      <geom type="mesh" contype="0" conaffinity="0" group="1" density="0" rgba="0.792157 0.819608 0.933333 1" mesh="link_SG3_gripper_finger_left"/>
                      <geom type="mesh" rgba="0.792157 0.819608 0.933333 1" mesh="link_SG3_gripper_finger_left_collision"/>
                      <geom pos="0.177785 -0.0106722 0" quat="0.092296 0.092296 0.701057 0.701057" type="mesh" contype="0" conaffinity="0" group="1" density="0" rgba="0.25098 0.25098 0.25098 1" mesh="link_SG3_gripper_fingertip_left"/>
                      <geom pos="0.177785 -0.0106722 0" quat="0.092296 0.092296 0.701057 0.701057" type="mesh" rgba="0.25098 0.25098 0.25098 1" mesh="link_SG3_gripper_fingertip_left_collision"/>
                      <geom pos="0.143935 -0.00436382 -8.5864e-05" quat="0.564208 -0.684439 -0.356297 0.293708" type="mesh" contype="0" conaffinity="0" group="1" density="0" rgba="1 1 1 1" mesh="link_SG3_aruco_fingertip_left"/>
                      <geom pos="0.143935 -0.00436382 -8.5864e-05" quat="0.564208 -0.684439 -0.356297 0.293708" type="mesh" rgba="1 1 1 1" mesh="link_SG3_aruco_fingertip_left"/>
                    </body>
                  </body>
                </body>
              </body>
            </body>
          </body>
        </body>
      </body>
    </body>
    <body name="link_head_pan" pos="0.00610002 -4.87362e-06 1.3552" quat="-1 -1.8366e-06 3.67321e-06 6.74255e-12">
      <inertial pos="-0.000422 0.013934 -0.0161" quat="0.485411 -0.16005 0.262062 0.818586" mass="0.062462" diaginertia="4.35701e-05 4.0243e-05 1.11869e-05"/>
      <joint name="joint_head_pan" pos="0 0 0" axis="0 0 1" range="-3.9 1.5" actuatorfrcrange="-100 100"/>
      <geom type="mesh" contype="0" conaffinity="0" group="1" density="0" rgba="0.792157 0.819608 0.933333 1" mesh="link_head_pan"/>
      <geom type="mesh" rgba="0.792157 0.819608 0.933333 1" mesh="link_head_pan_collision"/>
      <body name="link_head_tilt" pos="-0.0013 0.0277625 -0.0533108" quat="0.707107 0.707107 0 0">
        <inertial pos="0.012435 -0.0199108 0.0262329" quat="0.659664 0.662134 -0.258093 0.244561" mass="0.383894" diaginertia="0.00436506 0.00432125 0.000806024"/>
        <joint name="joint_head_tilt" pos="0 0 0" axis="0 0 1" range="-1.53 0.79" actuatorfrcrange="-100 100"/>
        <geom type="mesh" contype="0" conaffinity="0" group="1" density="0" rgba="0.792157 0.819608 0.933333 1" mesh="link_head_tilt"/>
        <geom type="mesh" rgba="0.792157 0.819608 0.933333 1" mesh="link_head_tilt_collision"/>
        <geom pos="0.0449 -0.0122 0.0307" quat="0.5 0.5 0.5 0.5" type="mesh" contype="0" conaffinity="0" group="1" density="0" mesh="d435"/>
        <geom size="0.012525 0.045 0.0125" pos="0.0406 -0.0122 0.0307" type="box"/>
        <geom pos="0.0402 -0.041173 -0.0245786" quat="0.707107 0 0.707107 0" type="mesh" contype="0" conaffinity="0" group="1" density="0" rgba="0.792157 0.819608 0.933333 1" mesh="link_SE3_head_nav_cam"/>
        <geom pos="0.0402 -0.041173 -0.0245786" quat="0.707107 0 0.707107 0" type="mesh" rgba="0.792157 0.819608 0.933333 1" mesh="link_SE3_head_nav_cam_collision"/>
      </body>
    </body>
  </worldbody>

  <contact>
    <exclude body1="link_head_pan" body2="link_head"/>
    <exclude body1="link_left_wheel" body2="base_link"/>
    <exclude body1="link_right_wheel" body2="base_link"/>
    <exclude body1="link_lift" body2="link_mast"/>
    <exclude body1="link_lift" body2="link_head"/>
    <exclude body1="link_arm_l0" body2="link_arm_l4"/>
    <exclude body1="link_arm_l1" body2="link_arm_l4"/>
    <exclude body1="link_arm_l2" body2="link_arm_l4"/>
    <exclude body1="link_arm_l3" body2="link_arm_l4"/>
    <exclude body1="link_arm_l0" body2="link_arm_l2"/>
    <exclude body1="link_arm_l0" body2="link_arm_l3"/>
    <exclude body1="link_arm_l0" body2="link_lift"/>
    <exclude body1="link_arm_l1" body2="link_arm_l3"/>
    <exclude body1="link_arm_l1" body2="link_lift"/>
    <exclude body1="link_arm_l2" body2="link_lift"/>
    <exclude body1="link_gripper_finger_left" body2="link_wrist_yaw"/>
    <exclude body1="link_gripper_finger_right" body2="link_wrist_yaw"/>
  </contact>

  <tendon>
    <fixed name="forward">
      <joint joint="joint_left_wheel" coef=".5"/>
      <joint joint="joint_right_wheel" coef=".5"/>
    </fixed>
    <fixed name="turn">
      <joint joint="joint_left_wheel" coef="-.5"/>
      <joint joint="joint_right_wheel" coef=".5"/>
    </fixed>
    <fixed name="extend">
      <joint joint="joint_arm_l0" coef="1"/>
      <joint joint="joint_arm_l1" coef="1"/>
      <joint joint="joint_arm_l2" coef="1"/>
      <joint joint="joint_arm_l3" coef="1"/>
    </fixed>
  </tendon>

  <equality>
    <joint joint1="joint_arm_l0" joint2="joint_arm_l1"/>
    <joint joint1="joint_arm_l1" joint2="joint_arm_l2"/>
    <joint joint1="joint_arm_l2" joint2="joint_arm_l3"/>
    <joint joint1="joint_gripper_finger_left_open" joint2="joint_gripper_slide" polycoef="0 10 0 0 0" solref="0.005 1"/>
    <joint joint1="joint_gripper_finger_right_open" joint2="joint_gripper_slide" polycoef="0 10 0 0 0" solref="0.005 1"/>
  </equality>

  <actuator>
    <motor name="forward" tendon="forward" class="wheel"/>
    <motor name="turn" tendon="turn" class="wheel"/>
    <general name="lift" joint="joint_lift" class="lift"/>
    <general name="arm_extend" tendon="extend" class="telescope"/>
    <general name="wrist_yaw" joint="joint_wrist_yaw" class="wrist"/>
    <general name="grip" joint="joint_gripper_slide" class="finger_slide"/>
    <position name="head_pan" joint="joint_head_pan" class="head_pan"/>
    <position name="head_tilt" joint="joint_head_tilt" class="head_tilt"/>
  </actuator>
</mujoco>
